[2024-06-18T15:36:20.098+0530] {taskinstance.py:1087} INFO - Dependencies all met for <TaskInstance: file_sensor_dag.trigger_another_dag manual__2024-06-18T10:06:16+00:00 [queued]>
[2024-06-18T15:36:20.102+0530] {taskinstance.py:1087} INFO - Dependencies all met for <TaskInstance: file_sensor_dag.trigger_another_dag manual__2024-06-18T10:06:16+00:00 [queued]>
[2024-06-18T15:36:20.102+0530] {taskinstance.py:1283} INFO - 
--------------------------------------------------------------------------------
[2024-06-18T15:36:20.102+0530] {taskinstance.py:1284} INFO - Starting attempt 1 of 2
[2024-06-18T15:36:20.102+0530] {taskinstance.py:1285} INFO - 
--------------------------------------------------------------------------------
[2024-06-18T15:36:20.109+0530] {taskinstance.py:1304} INFO - Executing <Task(TriggerDagRunOperator): trigger_another_dag> on 2024-06-18 10:06:16+00:00
[2024-06-18T15:36:20.112+0530] {standard_task_runner.py:55} INFO - Started process 246123 to run task
[2024-06-18T15:36:20.114+0530] {standard_task_runner.py:82} INFO - Running: ['airflow', 'tasks', 'run', 'file_sensor_dag', 'trigger_another_dag', 'manual__2024-06-18T10:06:16+00:00', '--job-id', '20', '--raw', '--subdir', 'DAGS_FOLDER/file_sensor_dag.py', '--cfg-path', '/tmp/tmp8zm6bvbv']
[2024-06-18T15:36:20.115+0530] {standard_task_runner.py:83} INFO - Job 20: Subtask trigger_another_dag
[2024-06-18T15:36:20.140+0530] {task_command.py:389} INFO - Running <TaskInstance: file_sensor_dag.trigger_another_dag manual__2024-06-18T10:06:16+00:00 [running]> on host purecipher002
[2024-06-18T15:36:20.170+0530] {taskinstance.py:1511} INFO - Exporting the following env vars:
AIRFLOW_CTX_DAG_OWNER=airflow
AIRFLOW_CTX_DAG_ID=file_sensor_dag
AIRFLOW_CTX_TASK_ID=trigger_another_dag
AIRFLOW_CTX_EXECUTION_DATE=2024-06-18T10:06:16+00:00
AIRFLOW_CTX_TRY_NUMBER=1
AIRFLOW_CTX_DAG_RUN_ID=manual__2024-06-18T10:06:16+00:00
[2024-06-18T15:36:20.175+0530] {taskinstance.py:1772} ERROR - Task failed with exception
Traceback (most recent call last):
  File "/home/e0002/airflow/airflow_venv/lib/python3.10/site-packages/airflow/operators/trigger_dagrun.py", line 139, in execute
    dag_run = trigger_dag(
  File "/home/e0002/airflow/airflow_venv/lib/python3.10/site-packages/airflow/api/common/trigger_dag.py", line 119, in trigger_dag
    raise DagNotFound(f"Dag id {dag_id} not found in DagModel")
airflow.exceptions.DagNotFound: Dag id another_dag not found in DagModel
[2024-06-18T15:36:20.176+0530] {taskinstance.py:1322} INFO - Marking task as UP_FOR_RETRY. dag_id=file_sensor_dag, task_id=trigger_another_dag, execution_date=20240618T100616, start_date=20240618T100620, end_date=20240618T100620
[2024-06-18T15:36:20.181+0530] {standard_task_runner.py:100} ERROR - Failed to execute job 20 for task trigger_another_dag (Dag id another_dag not found in DagModel; 246123)
[2024-06-18T15:36:20.206+0530] {local_task_job.py:159} INFO - Task exited with return code 1
[2024-06-18T15:36:20.216+0530] {taskinstance.py:2582} INFO - 0 downstream tasks scheduled from follow-on schedule check
